[2023-12-27T15:49:18.176+0000] {taskinstance.py:1165} INFO - Dependencies all met for <TaskInstance: salesforce_contact_processing.create_table scheduled__2023-12-26T00:00:00+00:00 [queued]>
[2023-12-27T15:49:18.215+0000] {taskinstance.py:1165} INFO - Dependencies all met for <TaskInstance: salesforce_contact_processing.create_table scheduled__2023-12-26T00:00:00+00:00 [queued]>
[2023-12-27T15:49:18.216+0000] {taskinstance.py:1362} INFO - 
--------------------------------------------------------------------------------
[2023-12-27T15:49:18.218+0000] {taskinstance.py:1363} INFO - Starting attempt 1 of 1
[2023-12-27T15:49:18.219+0000] {taskinstance.py:1364} INFO - 
--------------------------------------------------------------------------------
[2023-12-27T15:49:18.255+0000] {taskinstance.py:1383} INFO - Executing <Task(PostgresOperator): create_table> on 2023-12-26 00:00:00+00:00
[2023-12-27T15:49:18.289+0000] {standard_task_runner.py:55} INFO - Started process 27269 to run task
[2023-12-27T15:49:18.301+0000] {standard_task_runner.py:82} INFO - Running: ['***', 'tasks', 'run', 'salesforce_contact_processing', 'create_table', 'scheduled__2023-12-26T00:00:00+00:00', '--job-id', '27', '--raw', '--subdir', 'DAGS_FOLDER/salesforce_contact_processing.py', '--cfg-path', '/tmp/tmpkp10w270']
[2023-12-27T15:49:18.311+0000] {standard_task_runner.py:83} INFO - Job 27: Subtask create_table
[2023-12-27T15:49:18.655+0000] {task_command.py:376} INFO - Running <TaskInstance: salesforce_contact_processing.create_table scheduled__2023-12-26T00:00:00+00:00 [running]> on host bbee0f1e1252
[2023-12-27T15:49:18.995+0000] {taskinstance.py:1592} INFO - Exporting the following env vars:
AIRFLOW_CTX_DAG_OWNER=***
AIRFLOW_CTX_DAG_ID=salesforce_contact_processing
AIRFLOW_CTX_TASK_ID=create_table
AIRFLOW_CTX_EXECUTION_DATE=2023-12-26T00:00:00+00:00
AIRFLOW_CTX_TRY_NUMBER=1
AIRFLOW_CTX_DAG_RUN_ID=scheduled__2023-12-26T00:00:00+00:00
[2023-12-27T15:49:19.043+0000] {base.py:71} INFO - Using connection ID 'postgres' for task execution.
[2023-12-27T15:49:19.056+0000] {sql.py:315} INFO - Running statement: 
            CREATE TABLE IF NOT EXISTS contacts (
                name TEXT NOT NULL,
                title TEXT NOT NULL,
                department TEXT NOT NULL,
                email TEXT NOT NULL,
                gender TEXT NOT NULL
            );
        , parameters: None
[2023-12-27T15:49:19.071+0000] {taskinstance.py:1851} ERROR - Task failed with exception
Traceback (most recent call last):
  File "/home/airflow/.local/lib/python3.7/site-packages/airflow/providers/postgres/operators/postgres.py", line 94, in execute
    self.hook.run(self.sql, self.autocommit, parameters=self.parameters)
  File "/home/airflow/.local/lib/python3.7/site-packages/airflow/providers/common/sql/hooks/sql.py", line 295, in run
    self._run_command(cur, sql_statement, parameters)
  File "/home/airflow/.local/lib/python3.7/site-packages/airflow/providers/common/sql/hooks/sql.py", line 320, in _run_command
    cur.execute(sql_statement)
psycopg2.errors.UniqueViolation: duplicate key value violates unique constraint "pg_type_typname_nsp_index"
DETAIL:  Key (typname, typnamespace)=(contacts, 2200) already exists.

[2023-12-27T15:49:19.103+0000] {taskinstance.py:1406} INFO - Marking task as FAILED. dag_id=salesforce_contact_processing, task_id=create_table, execution_date=20231226T000000, start_date=20231227T154918, end_date=20231227T154919
[2023-12-27T15:49:19.162+0000] {standard_task_runner.py:105} ERROR - Failed to execute job 27 for task create_table (duplicate key value violates unique constraint "pg_type_typname_nsp_index"
DETAIL:  Key (typname, typnamespace)=(contacts, 2200) already exists.
; 27269)
[2023-12-27T15:49:19.261+0000] {local_task_job.py:164} INFO - Task exited with return code 1
[2023-12-27T15:49:19.450+0000] {local_task_job.py:273} INFO - 0 downstream tasks scheduled from follow-on schedule check
