[2023-12-26T04:28:46.549+0000] {taskinstance.py:1165} INFO - Dependencies all met for <TaskInstance: potential_customers_process.extract_customer manual__2023-12-26T04:28:43.432925+00:00 [queued]>
[2023-12-26T04:28:46.561+0000] {taskinstance.py:1165} INFO - Dependencies all met for <TaskInstance: potential_customers_process.extract_customer manual__2023-12-26T04:28:43.432925+00:00 [queued]>
[2023-12-26T04:28:46.561+0000] {taskinstance.py:1362} INFO - 
--------------------------------------------------------------------------------
[2023-12-26T04:28:46.561+0000] {taskinstance.py:1363} INFO - Starting attempt 1 of 1
[2023-12-26T04:28:46.561+0000] {taskinstance.py:1364} INFO - 
--------------------------------------------------------------------------------
[2023-12-26T04:28:46.569+0000] {taskinstance.py:1383} INFO - Executing <Task(PythonOperator): extract_customer> on 2023-12-26 04:28:43.432925+00:00
[2023-12-26T04:28:46.573+0000] {standard_task_runner.py:55} INFO - Started process 27256 to run task
[2023-12-26T04:28:46.576+0000] {standard_task_runner.py:82} INFO - Running: ['***', 'tasks', 'run', 'potential_customers_process', 'extract_customer', 'manual__2023-12-26T04:28:43.432925+00:00', '--job-id', '85', '--raw', '--subdir', 'DAGS_FOLDER/potential_customers_process.py', '--cfg-path', '/tmp/tmpkbcwrf37']
[2023-12-26T04:28:46.577+0000] {standard_task_runner.py:83} INFO - Job 85: Subtask extract_customer
[2023-12-26T04:28:46.611+0000] {task_command.py:376} INFO - Running <TaskInstance: potential_customers_process.extract_customer manual__2023-12-26T04:28:43.432925+00:00 [running]> on host 2d20203c1be8
[2023-12-26T04:28:46.646+0000] {taskinstance.py:1592} INFO - Exporting the following env vars:
AIRFLOW_CTX_DAG_OWNER=***
AIRFLOW_CTX_DAG_ID=potential_customers_process
AIRFLOW_CTX_TASK_ID=extract_customer
AIRFLOW_CTX_EXECUTION_DATE=2023-12-26T04:28:43.432925+00:00
AIRFLOW_CTX_TRY_NUMBER=1
AIRFLOW_CTX_DAG_RUN_ID=manual__2023-12-26T04:28:43.432925+00:00
[2023-12-26T04:28:46.649+0000] {taskinstance.py:1851} ERROR - Task failed with exception
Traceback (most recent call last):
  File "/home/airflow/.local/lib/python3.7/site-packages/airflow/operators/python.py", line 175, in execute
    return_value = self.execute_callable()
  File "/home/airflow/.local/lib/python3.7/site-packages/airflow/operators/python.py", line 193, in execute_callable
    return self.python_callable(*self.op_args, **self.op_kwargs)
  File "/opt/airflow/dags/potential_customers_process.py", line 16, in _extract_customer
    file = read_csv("./data/customer.csv")
  File "/home/airflow/.local/lib/python3.7/site-packages/pandas/util/_decorators.py", line 311, in wrapper
    return func(*args, **kwargs)
  File "/home/airflow/.local/lib/python3.7/site-packages/pandas/io/parsers/readers.py", line 586, in read_csv
    return _read(filepath_or_buffer, kwds)
  File "/home/airflow/.local/lib/python3.7/site-packages/pandas/io/parsers/readers.py", line 482, in _read
    parser = TextFileReader(filepath_or_buffer, **kwds)
  File "/home/airflow/.local/lib/python3.7/site-packages/pandas/io/parsers/readers.py", line 811, in __init__
    self._engine = self._make_engine(self.engine)
  File "/home/airflow/.local/lib/python3.7/site-packages/pandas/io/parsers/readers.py", line 1040, in _make_engine
    return mapping[engine](self.f, **self.options)  # type: ignore[call-arg]
  File "/home/airflow/.local/lib/python3.7/site-packages/pandas/io/parsers/c_parser_wrapper.py", line 51, in __init__
    self._open_handles(src, kwds)
  File "/home/airflow/.local/lib/python3.7/site-packages/pandas/io/parsers/base_parser.py", line 229, in _open_handles
    errors=kwds.get("encoding_errors", "strict"),
  File "/home/airflow/.local/lib/python3.7/site-packages/pandas/io/common.py", line 707, in get_handle
    newline="",
FileNotFoundError: [Errno 2] No such file or directory: './data/customer.csv'
[2023-12-26T04:28:46.656+0000] {taskinstance.py:1406} INFO - Marking task as FAILED. dag_id=potential_customers_process, task_id=extract_customer, execution_date=20231226T042843, start_date=20231226T042846, end_date=20231226T042846
[2023-12-26T04:28:46.662+0000] {standard_task_runner.py:105} ERROR - Failed to execute job 85 for task extract_customer ([Errno 2] No such file or directory: './data/customer.csv'; 27256)
[2023-12-26T04:28:46.668+0000] {local_task_job.py:164} INFO - Task exited with return code 1
[2023-12-26T04:28:46.679+0000] {local_task_job.py:273} INFO - 0 downstream tasks scheduled from follow-on schedule check
