[2023-12-27T16:05:23.245+0000] {taskinstance.py:1165} INFO - Dependencies all met for <TaskInstance: salesforce_contact_processing.extract_user manual__2023-12-27T16:05:19.994785+00:00 [queued]>
[2023-12-27T16:05:23.251+0000] {taskinstance.py:1165} INFO - Dependencies all met for <TaskInstance: salesforce_contact_processing.extract_user manual__2023-12-27T16:05:19.994785+00:00 [queued]>
[2023-12-27T16:05:23.251+0000] {taskinstance.py:1362} INFO - 
--------------------------------------------------------------------------------
[2023-12-27T16:05:23.251+0000] {taskinstance.py:1363} INFO - Starting attempt 1 of 1
[2023-12-27T16:05:23.251+0000] {taskinstance.py:1364} INFO - 
--------------------------------------------------------------------------------
[2023-12-27T16:05:23.258+0000] {taskinstance.py:1383} INFO - Executing <Task(SimpleHttpOperator): extract_user> on 2023-12-27 16:05:19.994785+00:00
[2023-12-27T16:05:23.262+0000] {standard_task_runner.py:55} INFO - Started process 28096 to run task
[2023-12-27T16:05:23.264+0000] {standard_task_runner.py:82} INFO - Running: ['***', 'tasks', 'run', 'salesforce_contact_processing', 'extract_user', 'manual__2023-12-27T16:05:19.994785+00:00', '--job-id', '45', '--raw', '--subdir', 'DAGS_FOLDER/salesforce_contact_processing.py', '--cfg-path', '/tmp/tmpnovtawqx']
[2023-12-27T16:05:23.266+0000] {standard_task_runner.py:83} INFO - Job 45: Subtask extract_user
[2023-12-27T16:05:23.300+0000] {task_command.py:376} INFO - Running <TaskInstance: salesforce_contact_processing.extract_user manual__2023-12-27T16:05:19.994785+00:00 [running]> on host bbee0f1e1252
[2023-12-27T16:05:23.336+0000] {taskinstance.py:1592} INFO - Exporting the following env vars:
AIRFLOW_CTX_DAG_OWNER=***
AIRFLOW_CTX_DAG_ID=salesforce_contact_processing
AIRFLOW_CTX_TASK_ID=extract_user
AIRFLOW_CTX_EXECUTION_DATE=2023-12-27T16:05:19.994785+00:00
AIRFLOW_CTX_TRY_NUMBER=1
AIRFLOW_CTX_DAG_RUN_ID=manual__2023-12-27T16:05:19.994785+00:00
[2023-12-27T16:05:23.337+0000] {http.py:121} INFO - Calling HTTP method
[2023-12-27T16:05:23.342+0000] {base.py:71} INFO - Using connection ID 'salesforce' for task execution.
[2023-12-27T16:05:23.343+0000] {http.py:148} INFO - Sending 'GET' to url: https://codelink-dev-ed.develop.my.salesforce.com/services/data/v59.0/query?q=SELECT+FIELDS(STANDARD)+from+Contact
[2023-12-27T16:05:24.053+0000] {http.py:161} ERROR - HTTP error: Unauthorized
[2023-12-27T16:05:24.053+0000] {http.py:162} ERROR - [{"message":"INVALID_AUTH_HEADER","errorCode":"INVALID_AUTH_HEADER"}]
[2023-12-27T16:05:24.060+0000] {taskinstance.py:1851} ERROR - Task failed with exception
Traceback (most recent call last):
  File "/home/airflow/.local/lib/python3.7/site-packages/airflow/providers/http/hooks/http.py", line 159, in check_response
    response.raise_for_status()
  File "/home/airflow/.local/lib/python3.7/site-packages/requests/models.py", line 1021, in raise_for_status
    raise HTTPError(http_error_msg, response=self)
requests.exceptions.HTTPError: 401 Client Error: Unauthorized for url: https://codelink-dev-ed.develop.my.salesforce.com/services/data/v59.0/query?q=SELECT+FIELDS(STANDARD)+from+Contact

During handling of the above exception, another exception occurred:

Traceback (most recent call last):
  File "/home/airflow/.local/lib/python3.7/site-packages/airflow/providers/http/operators/http.py", line 123, in execute
    response = http.run(self.endpoint, self.data, self.headers, self.extra_options)
  File "/home/airflow/.local/lib/python3.7/site-packages/airflow/providers/http/hooks/http.py", line 149, in run
    return self.run_and_check(session, prepped_request, extra_options)
  File "/home/airflow/.local/lib/python3.7/site-packages/airflow/providers/http/hooks/http.py", line 202, in run_and_check
    self.check_response(response)
  File "/home/airflow/.local/lib/python3.7/site-packages/airflow/providers/http/hooks/http.py", line 163, in check_response
    raise AirflowException(str(response.status_code) + ":" + response.reason)
airflow.exceptions.AirflowException: 401:Unauthorized
[2023-12-27T16:05:24.064+0000] {taskinstance.py:1406} INFO - Marking task as FAILED. dag_id=salesforce_contact_processing, task_id=extract_user, execution_date=20231227T160519, start_date=20231227T160523, end_date=20231227T160524
[2023-12-27T16:05:24.073+0000] {standard_task_runner.py:105} ERROR - Failed to execute job 45 for task extract_user (401:Unauthorized; 28096)
[2023-12-27T16:05:24.118+0000] {local_task_job.py:164} INFO - Task exited with return code 1
[2023-12-27T16:05:24.135+0000] {local_task_job.py:273} INFO - 0 downstream tasks scheduled from follow-on schedule check
